Workbook

Sheet Sheet1
A1: date | B1: recettes | C1: dépenses | D1: total par jour | E1: total | F1: dispo | G1: pieces | H1: nombre
A2: 45761 | B2: 1.75 | C2: 0 | D2: =B2-C2 -> 1.75 | E2: =(SUM(B2:B1000)-SUM(C2:C1000)+Sheet2!F2) -> 15.35 | F2: =0.8*E2 -> 12.28 | G2: 500 | H2: 0
A3: 45762 | B3: =2.25-1.75 -> 0.5 | C3: 0 | D3: =B3-C3+D2 -> 2.25 | F3: =IF(Sheet2!B3<0,F2-Sheet2!B3,F2) -> 12.28 | G3: 200 | H3: 0
A4: 45763 | B4: =7.93-2.25 -> 5.68 | C4: 0 | D4: =B4-C4+D3 -> 7.93 | G4: 100 | H4: 0
A5: 45764 | B5: 0.1 | C5: 0 | D5: =B5-C5+D4 -> 8.03 | G5: 50 | H5: 0
A6: 45765 | C6: 0 | D6: =B6-C6+D5 -> 8.03 | G6: 20 | H6: 0
A7: 45766 | C7: 0 | D7: =B7-C7+D6 -> 8.03 | G7: 10 | H7: 0
A8: 45767 | C8: 0 | D8: =B8-C8+D7 -> 8.03 | G8: 5 | H8: 0
A9: 45768 | C9: 0 | D9: =B9-C9+D8 -> 8.03 | G9: 2 | H9: 0
A10: 45769 | C10: 0 | D10: =B10-C10+D9 -> 8.03 | G10: 1 | H10: 1
A11: 45770 | C11: 0 | D11: =B11-C11+D10 -> 8.03 | G11: 0.5 | H11: 2
A12: 45771 | C12: 0 | D12: =B12-C12+D11 -> 8.03 | G12: 0.2 | H12: =9+3+1 -> 13
A13: 45772 | C13: 0 | D13: =B13-C13+D12 -> 8.03 | G13: 0.1 | H13: =6+3 -> 9
A14: 45773 | C14: 0 | D14: =B14-C14+D13 -> 8.03 | G14: 0.05 | H14: 113
A15: 45774 | C15: 0 | D15: =B15-C15+D14 -> 8.03 | G15: 0.02 | H15: =90+2+59 -> 151
A16: 45775 | C16: 0 | D16: =B16-C16+D15 -> 8.03 | G16: 0.01 | H16: 108
A17: 45776 | C17: 0 | D17: =B17-C17+D16 -> 8.03 | H17: =SUM(H2:H16) -> 397
A18: 45777 | B18: 0.05 | C18: 0 | D18: =B18-C18+D17 -> 8.08
A19: 45778 | C19: 0 | D19: =B19-C19+D18 -> 8.08
A20: 45779 | C20: 0 | D20: =B20-C20+D19 -> 8.08
A21: 45780 | C21: 0 | D21: =B21-C21+D20 -> 8.08
A22: 45781 | C22: 0 | D22: =B22-C22+D21 -> 8.08
A23: 45782 | C23: 0 | D23: =B23-C23+D22 -> 8.08
A24: 45783 | B24: 0.01 | C24: 0 | D24: =B24-C24+D23 -> 8.09
A25: 45784 | B25: 0.2 | C25: 0 | D25: =B25-C25+D24 -> 8.29
A26: 45785 | C26: 0 | D26: =B26-C26+D25 -> 8.29
A27: 45786 | C27: 0 | D27: =B27-C27+D26 -> 8.29
A28: 45787 | C28: 0 | D28: =B28-C28+D27 -> 8.29
A29: 45788 | B29: 0.02 | C29: 0 | D29: =B29-C29+D28 -> 8.31
A30: 45789 | B30: 0.6 | C30: 0 | D30: =B30-C30+D29 -> 8.91
A31: 45790 | C31: 0 | D31: =B31-C31+D30 -> 8.91
A32: 45791 | C32: 0 | D32: =B32-C32+D31 -> 8.91
A33: 45792 | C33: 0 | D33: =B33-C33+D32 -> 8.91
A34: 45793 | B34: 0.01 | C34: 0 | D34: =B34-C34+D33 -> 8.92
A35: 45794 | C35: 0 | D35: =B35-C35+D34 -> 8.92
A36: 45795 | C36: 0 | D36: =B36-C36+D35 -> 8.92
A37: 45796 | C37: 0 | D37: =B37-C37+D36 -> 8.92
A38: 45797 | C38: 0 | D38: =B38-C38+D37 -> 8.92
A39: 45798 | C39: 0 | D39: =B39-C39+D38 -> 8.92
A40: 45799 | B40: 1.26 | C40: 0 | D40: =B40-C40+D39 -> 10.18
...

Sheet Sheet2
A1: total dispo crypto | B1: dispo crypto | C1: crypto | D1: gain | E1: perte | F1: total
A2: =Sheet1!E2*0.15 -> 2.3025 | B2: =A2-C2 -> 2.3025 | F2: =D2+E2 -> 0
A3: =0.05*Sheet1!E2 -> 0.7675 | B3: =B2+A3 -> 3.07

Sheet Sheet3
A1: objet | B1: prix unit | C1: nb | D1: prix | E1: Argent manquant | F1: Action
A2: clef USB 2To | B2: 6 | C2: 1 | D2: =B2*C2 -> 6 | E2: =IF(D2-Sheet1!E2<0,0,D2-Sheet1!E2) -> 0 | F2: =IF(E2<0,"Argent suffisant","argent insuffisant") -> argent insuffisant
